ERROR 2017-02-08 10:18:03,424 views 6411 140350626912000 ÈÇÆ‰ª∂ÂèëÈÄÅÂ§±Ë¥•: (535, b'5.7.8 authentication failed')ERROR 2017-10-07 10:11:28,866 exception 12102 140324119840512 Internal Server Error: /
Traceback (most recent call last):
  File "/home/ming/.env/blog/lib/python3.5/site-packages/django/db/backends/utils.py", line 64, in execute
    return self.cursor.execute(sql, params)
  File "/home/ming/.env/blog/lib/python3.5/site-packages/django/db/backends/mysql/base.py", line 112, in execute
    return self.cursor.execute(query, args)
  File "/home/ming/.env/blog/lib/python3.5/site-packages/pymysql/cursors.py", line 166, in execute
    result = self._query(query)
  File "/home/ming/.env/blog/lib/python3.5/site-packages/pymysql/cursors.py", line 322, in _query
    conn.query(q)
  File "/home/ming/.env/blog/lib/python3.5/site-packages/pymysql/connections.py", line 856, in query
    self._affected_rows = self._read_query_result(unbuffered=unbuffered)
  File "/home/ming/.env/blog/lib/python3.5/site-packages/pymysql/connections.py", line 1057, in _read_query_result
    result.read()
  File "/home/ming/.env/blog/lib/python3.5/site-packages/pymysql/connections.py", line 1340, in read
    first_packet = self.connection._read_packet()
  File "/home/ming/.env/blog/lib/python3.5/site-packages/pymysql/connections.py", line 1014, in _read_packet
    packet.check_error()
  File "/home/ming/.env/blog/lib/python3.5/site-packages/pymysql/connections.py", line 393, in check_error
    err.raise_mysql_exception(self._data)
  File "/home/ming/.env/blog/lib/python3.5/site-packages/pymysql/err.py", line 107, in raise_mysql_exception
    raise errorclass(errno, errval)
pymysql.err.ProgrammingError: (1146, "Table 'blog.app_article' doesn't exist")

The above exception was the direct cause of the following exception:

Traceback (most recent call last):
  File "/home/ming/.env/blog/lib/python3.5/site-packages/django/core/handlers/exception.py", line 39, in inner
    response = get_response(request)
  File "/home/ming/.env/blog/lib/python3.5/site-packages/django/core/handlers/base.py", line 187, in _get_response
    response = self.process_exception_by_middleware(e, request)
  File "/home/ming/.env/blog/lib/python3.5/site-packages/django/core/handlers/base.py", line 185, in _get_response
    response = wrapped_callback(request, *callback_args, **callback_kwargs)
  File "/home/ming/.env/blog/lib/python3.5/site-packages/django/views/generic/base.py", line 68, in view
    return self.dispatch(request, *args, **kwargs)
  File "/home/ming/.env/blog/lib/python3.5/site-packages/django/views/generic/base.py", line 88, in dispatch
    return handler(request, *args, **kwargs)
  File "/home/ming/.env/blog/lib/python3.5/site-packages/django/views/generic/list.py", line 159, in get
    self.object_list = self.get_queryset()
  File "/home/ming/projects/blog/app/views.py", line 29, in get_queryset
    for article in article_list:
  File "/home/ming/.env/blog/lib/python3.5/site-packages/django/db/models/query.py", line 256, in __iter__
    self._fetch_all()
  File "/home/ming/.env/blog/lib/python3.5/site-packages/django/db/models/query.py", line 1087, in _fetch_all
    self._result_cache = list(self.iterator())
  File "/home/ming/.env/blog/lib/python3.5/site-packages/django/db/models/query.py", line 54, in __iter__
    results = compiler.execute_sql()
  File "/home/ming/.env/blog/lib/python3.5/site-packages/django/db/models/sql/compiler.py", line 835, in execute_sql
    cursor.execute(sql, params)
  File "/home/ming/.env/blog/lib/python3.5/site-packages/django/db/backends/utils.py", line 79, in execute
    return super(CursorDebugWrapper, self).execute(sql, params)
  File "/home/ming/.env/blog/lib/python3.5/site-packages/django/db/backends/utils.py", line 64, in execute
    return self.cursor.execute(sql, params)
  File "/home/ming/.env/blog/lib/python3.5/site-packages/django/db/utils.py", line 94, in __exit__
    six.reraise(dj_exc_type, dj_exc_value, traceback)
  File "/home/ming/.env/blog/lib/python3.5/site-packages/django/utils/six.py", line 685, in reraise
    raise value.with_traceback(tb)
  File "/home/ming/.env/blog/lib/python3.5/site-packages/django/db/backends/utils.py", line 64, in execute
    return self.cursor.execute(sql, params)
  File "/home/ming/.env/blog/lib/python3.5/site-packages/django/db/backends/mysql/base.py", line 112, in execute
    return self.cursor.execute(query, args)
  File "/home/ming/.env/blog/lib/python3.5/site-packages/pymysql/cursors.py", line 166, in execute
    result = self._query(query)
  File "/home/ming/.env/blog/lib/python3.5/site-packages/pymysql/cursors.py", line 322, in _query
    conn.query(q)
  File "/home/ming/.env/blog/lib/python3.5/site-packages/pymysql/connections.py", line 856, in query
    self._affected_rows = self._read_query_result(unbuffered=unbuffered)
  File "/home/ming/.env/blog/lib/python3.5/site-packages/pymysql/connections.py", line 1057, in _read_query_result
    result.read()
  File "/home/ming/.env/blog/lib/python3.5/site-packages/pymysql/connections.py", line 1340, in read
    first_packet = self.connection._read_packet()
  File "/home/ming/.env/blog/lib/python3.5/site-packages/pymysql/connections.py", line 1014, in _read_packet
    packet.check_error()
  File "/home/ming/.env/blog/lib/python3.5/site-packages/pymysql/connections.py", line 393, in check_error
    err.raise_mysql_exception(self._data)
  File "/home/ming/.env/blog/lib/python3.5/site-packages/pymysql/err.py", line 107, in raise_mysql_exception
    raise errorclass(errno, errval)
django.db.utils.ProgrammingError: (1146, "Table 'blog.app_article' doesn't exist")
ERROR 2017-10-07 10:24:31,582 views 13373 140030823622400 ÈÇÆ‰ª∂ÂèëÈÄÅÂ§±Ë¥•: Error 111 connecting to localhost:6379. Connection refused.
ERROR 2017-10-07 11:02:40,385 views 26434 139984518506240 ÈÇÆ‰ª∂ÂèëÈÄÅÂ§±Ë¥•: (535, b'5.7.8 authentication failed')
ERROR 2017-10-07 11:03:13,011 views 26595 140543109977856 ÈÇÆ‰ª∂ÂèëÈÄÅÂ§±Ë¥•: (535, b'5.7.12 SMTP access disabled')
ERROR 2017-12-06 13:43:39,729 exception 3532 5556 Internal Server Error: /article/3
Traceback (most recent call last):
  File "D:\Python36\lib\site-packages\django_redis\cache.py", line 34, in _decorator
    return method(self, *args, **kwargs)
  File "D:\Python36\lib\site-packages\django_redis\cache.py", line 83, in get
    client=client)
  File "D:\Python36\lib\site-packages\django_redis\client\default.py", line 209, in get
    raise ConnectionInterrupted(connection=client, parent=e)
django_redis.exceptions.ConnectionInterrupted: Redis ConnectionError: Error 10061 connecting to 127.0.0.1:6379. ”…”⁄ƒø±Íº∆À„ª˙ª˝º´æ‹æ¯£¨Œﬁ∑®¡¨Ω”°£.

During handling of the above exception, another exception occurred:

Traceback (most recent call last):
  File "D:\Python36\lib\site-packages\django\core\handlers\exception.py", line 39, in inner
    response = get_response(request)
  File "D:\Python36\lib\site-packages\django\core\handlers\base.py", line 187, in _get_response
    response = self.process_exception_by_middleware(e, request)
  File "D:\Python36\lib\site-packages\django\core\handlers\base.py", line 185, in _get_response
    response = wrapped_callback(request, *callback_args, **callback_kwargs)
  File "D:\Python36\lib\site-packages\django\utils\decorators.py", line 141, in _wrapped_view
    result = middleware.process_request(request)
  File "D:\Python36\lib\site-packages\django\middleware\cache.py", line 133, in process_request
    cache_key = get_cache_key(request, self.key_prefix, 'GET', cache=self.cache)
  File "D:\Python36\lib\site-packages\django\utils\cache.py", line 318, in get_cache_key
    headerlist = cache.get(cache_key)
  File "D:\Python36\lib\site-packages\django_redis\cache.py", line 41, in _decorator
    raise e.parent
  File "D:\Python36\lib\site-packages\django_redis\client\default.py", line 207, in get
    value = client.get(key)
  File "D:\Python36\lib\site-packages\redis\client.py", line 880, in get
    return self.execute_command('GET', name)
  File "D:\Python36\lib\site-packages\redis\client.py", line 578, in execute_command
    connection.send_command(*args)
  File "D:\Python36\lib\site-packages\redis\connection.py", line 563, in send_command
    self.send_packed_command(self.pack_command(*args))
  File "D:\Python36\lib\site-packages\redis\connection.py", line 538, in send_packed_command
    self.connect()
  File "D:\Python36\lib\site-packages\redis\connection.py", line 442, in connect
    raise ConnectionError(self._error_message(e))
redis.exceptions.ConnectionError: Error 10061 connecting to 127.0.0.1:6379. ”…”⁄ƒø±Íº∆À„ª˙ª˝º´æ‹æ¯£¨Œﬁ∑®¡¨Ω”°£.
ERROR 2017-12-06 13:43:39,809 exception 3532 7104 Internal Server Error: /article/3
Traceback (most recent call last):
  File "D:\Python36\lib\site-packages\django_redis\cache.py", line 34, in _decorator
    return method(self, *args, **kwargs)
  File "D:\Python36\lib\site-packages\django_redis\cache.py", line 83, in get
    client=client)
  File "D:\Python36\lib\site-packages\django_redis\client\default.py", line 209, in get
    raise ConnectionInterrupted(connection=client, parent=e)
django_redis.exceptions.ConnectionInterrupted: Redis ConnectionError: Error 10061 connecting to 127.0.0.1:6379. ”…”⁄ƒø±Íº∆À„ª˙ª˝º´æ‹æ¯£¨Œﬁ∑®¡¨Ω”°£.

During handling of the above exception, another exception occurred:

Traceback (most recent call last):
  File "D:\Python36\lib\site-packages\django\core\handlers\exception.py", line 39, in inner
    response = get_response(request)
  File "D:\Python36\lib\site-packages\django\core\handlers\base.py", line 187, in _get_response
    response = self.process_exception_by_middleware(e, request)
  File "D:\Python36\lib\site-packages\django\core\handlers\base.py", line 185, in _get_response
    response = wrapped_callback(request, *callback_args, **callback_kwargs)
  File "D:\Python36\lib\site-packages\django\utils\decorators.py", line 141, in _wrapped_view
    result = middleware.process_request(request)
  File "D:\Python36\lib\site-packages\django\middleware\cache.py", line 133, in process_request
    cache_key = get_cache_key(request, self.key_prefix, 'GET', cache=self.cache)
  File "D:\Python36\lib\site-packages\django\utils\cache.py", line 318, in get_cache_key
    headerlist = cache.get(cache_key)
  File "D:\Python36\lib\site-packages\django_redis\cache.py", line 41, in _decorator
    raise e.parent
  File "D:\Python36\lib\site-packages\django_redis\client\default.py", line 207, in get
    value = client.get(key)
  File "D:\Python36\lib\site-packages\redis\client.py", line 880, in get
    return self.execute_command('GET', name)
  File "D:\Python36\lib\site-packages\redis\client.py", line 578, in execute_command
    connection.send_command(*args)
  File "D:\Python36\lib\site-packages\redis\connection.py", line 563, in send_command
    self.send_packed_command(self.pack_command(*args))
  File "D:\Python36\lib\site-packages\redis\connection.py", line 538, in send_packed_command
    self.connect()
  File "D:\Python36\lib\site-packages\redis\connection.py", line 442, in connect
    raise ConnectionError(self._error_message(e))
redis.exceptions.ConnectionError: Error 10061 connecting to 127.0.0.1:6379. ”…”⁄ƒø±Íº∆À„ª˙ª˝º´æ‹æ¯£¨Œﬁ∑®¡¨Ω”°£.
ERROR 2017-12-06 13:45:23,584 exception 3532 6980 Internal Server Error: /article/4
Traceback (most recent call last):
  File "D:\Python36\lib\site-packages\django_redis\cache.py", line 34, in _decorator
    return method(self, *args, **kwargs)
  File "D:\Python36\lib\site-packages\django_redis\cache.py", line 83, in get
    client=client)
  File "D:\Python36\lib\site-packages\django_redis\client\default.py", line 209, in get
    raise ConnectionInterrupted(connection=client, parent=e)
django_redis.exceptions.ConnectionInterrupted: Redis ConnectionError: Error 10061 connecting to 127.0.0.1:6379. ”…”⁄ƒø±Íº∆À„ª˙ª˝º´æ‹æ¯£¨Œﬁ∑®¡¨Ω”°£.

During handling of the above exception, another exception occurred:

Traceback (most recent call last):
  File "D:\Python36\lib\site-packages\django\core\handlers\exception.py", line 39, in inner
    response = get_response(request)
  File "D:\Python36\lib\site-packages\django\core\handlers\base.py", line 187, in _get_response
    response = self.process_exception_by_middleware(e, request)
  File "D:\Python36\lib\site-packages\django\core\handlers\base.py", line 185, in _get_response
    response = wrapped_callback(request, *callback_args, **callback_kwargs)
  File "D:\Python36\lib\site-packages\django\utils\decorators.py", line 141, in _wrapped_view
    result = middleware.process_request(request)
  File "D:\Python36\lib\site-packages\django\middleware\cache.py", line 133, in process_request
    cache_key = get_cache_key(request, self.key_prefix, 'GET', cache=self.cache)
  File "D:\Python36\lib\site-packages\django\utils\cache.py", line 318, in get_cache_key
    headerlist = cache.get(cache_key)
  File "D:\Python36\lib\site-packages\django_redis\cache.py", line 41, in _decorator
    raise e.parent
  File "D:\Python36\lib\site-packages\django_redis\client\default.py", line 207, in get
    value = client.get(key)
  File "D:\Python36\lib\site-packages\redis\client.py", line 880, in get
    return self.execute_command('GET', name)
  File "D:\Python36\lib\site-packages\redis\client.py", line 578, in execute_command
    connection.send_command(*args)
  File "D:\Python36\lib\site-packages\redis\connection.py", line 563, in send_command
    self.send_packed_command(self.pack_command(*args))
  File "D:\Python36\lib\site-packages\redis\connection.py", line 538, in send_packed_command
    self.connect()
  File "D:\Python36\lib\site-packages\redis\connection.py", line 442, in connect
    raise ConnectionError(self._error_message(e))
redis.exceptions.ConnectionError: Error 10061 connecting to 127.0.0.1:6379. ”…”⁄ƒø±Íº∆À„ª˙ª˝º´æ‹æ¯£¨Œﬁ∑®¡¨Ω”°£.
ERROR 2019-12-06 11:20:10,313 exception 64863 123145558691840 Internal Server Error: /
Traceback (most recent call last):
  File "/Users/yuyang/github/djangblog/.venv/lib/python3.7/site-packages/django/db/backends/utils.py", line 64, in execute
    return self.cursor.execute(sql, params)
  File "/Users/yuyang/github/djangblog/.venv/lib/python3.7/site-packages/django/db/backends/mysql/base.py", line 112, in execute
    return self.cursor.execute(query, args)
  File "/Users/yuyang/github/djangblog/.venv/lib/python3.7/site-packages/pymysql/cursors.py", line 166, in execute
    result = self._query(query)
  File "/Users/yuyang/github/djangblog/.venv/lib/python3.7/site-packages/pymysql/cursors.py", line 322, in _query
    conn.query(q)
  File "/Users/yuyang/github/djangblog/.venv/lib/python3.7/site-packages/pymysql/connections.py", line 856, in query
    self._affected_rows = self._read_query_result(unbuffered=unbuffered)
  File "/Users/yuyang/github/djangblog/.venv/lib/python3.7/site-packages/pymysql/connections.py", line 1057, in _read_query_result
    result.read()
  File "/Users/yuyang/github/djangblog/.venv/lib/python3.7/site-packages/pymysql/connections.py", line 1340, in read
    first_packet = self.connection._read_packet()
  File "/Users/yuyang/github/djangblog/.venv/lib/python3.7/site-packages/pymysql/connections.py", line 1014, in _read_packet
    packet.check_error()
  File "/Users/yuyang/github/djangblog/.venv/lib/python3.7/site-packages/pymysql/connections.py", line 393, in check_error
    err.raise_mysql_exception(self._data)
  File "/Users/yuyang/github/djangblog/.venv/lib/python3.7/site-packages/pymysql/err.py", line 107, in raise_mysql_exception
    raise errorclass(errno, errval)
pymysql.err.ProgrammingError: (1146, "Table 'blog.app_article' doesn't exist")

The above exception was the direct cause of the following exception:

Traceback (most recent call last):
  File "/Users/yuyang/github/djangblog/.venv/lib/python3.7/site-packages/django/core/handlers/exception.py", line 39, in inner
    response = get_response(request)
  File "/Users/yuyang/github/djangblog/.venv/lib/python3.7/site-packages/django/core/handlers/base.py", line 187, in _get_response
    response = self.process_exception_by_middleware(e, request)
  File "/Users/yuyang/github/djangblog/.venv/lib/python3.7/site-packages/django/core/handlers/base.py", line 185, in _get_response
    response = wrapped_callback(request, *callback_args, **callback_kwargs)
  File "/Users/yuyang/github/djangblog/.venv/lib/python3.7/site-packages/django/views/generic/base.py", line 68, in view
    return self.dispatch(request, *args, **kwargs)
  File "/Users/yuyang/github/djangblog/.venv/lib/python3.7/site-packages/django/views/generic/base.py", line 88, in dispatch
    return handler(request, *args, **kwargs)
  File "/Users/yuyang/github/djangblog/.venv/lib/python3.7/site-packages/django/views/generic/list.py", line 159, in get
    self.object_list = self.get_queryset()
  File "/Users/yuyang/github/djangblog/app/views.py", line 30, in get_queryset
    for article in article_list:
  File "/Users/yuyang/github/djangblog/.venv/lib/python3.7/site-packages/django/db/models/query.py", line 256, in __iter__
    self._fetch_all()
  File "/Users/yuyang/github/djangblog/.venv/lib/python3.7/site-packages/django/db/models/query.py", line 1087, in _fetch_all
    self._result_cache = list(self.iterator())
  File "/Users/yuyang/github/djangblog/.venv/lib/python3.7/site-packages/django/db/models/query.py", line 54, in __iter__
    results = compiler.execute_sql()
  File "/Users/yuyang/github/djangblog/.venv/lib/python3.7/site-packages/django/db/models/sql/compiler.py", line 835, in execute_sql
    cursor.execute(sql, params)
  File "/Users/yuyang/github/djangblog/.venv/lib/python3.7/site-packages/django/db/backends/utils.py", line 79, in execute
    return super(CursorDebugWrapper, self).execute(sql, params)
  File "/Users/yuyang/github/djangblog/.venv/lib/python3.7/site-packages/django/db/backends/utils.py", line 64, in execute
    return self.cursor.execute(sql, params)
  File "/Users/yuyang/github/djangblog/.venv/lib/python3.7/site-packages/django/db/utils.py", line 94, in __exit__
    six.reraise(dj_exc_type, dj_exc_value, traceback)
  File "/Users/yuyang/github/djangblog/.venv/lib/python3.7/site-packages/django/utils/six.py", line 685, in reraise
    raise value.with_traceback(tb)
  File "/Users/yuyang/github/djangblog/.venv/lib/python3.7/site-packages/django/db/backends/utils.py", line 64, in execute
    return self.cursor.execute(sql, params)
  File "/Users/yuyang/github/djangblog/.venv/lib/python3.7/site-packages/django/db/backends/mysql/base.py", line 112, in execute
    return self.cursor.execute(query, args)
  File "/Users/yuyang/github/djangblog/.venv/lib/python3.7/site-packages/pymysql/cursors.py", line 166, in execute
    result = self._query(query)
  File "/Users/yuyang/github/djangblog/.venv/lib/python3.7/site-packages/pymysql/cursors.py", line 322, in _query
    conn.query(q)
  File "/Users/yuyang/github/djangblog/.venv/lib/python3.7/site-packages/pymysql/connections.py", line 856, in query
    self._affected_rows = self._read_query_result(unbuffered=unbuffered)
  File "/Users/yuyang/github/djangblog/.venv/lib/python3.7/site-packages/pymysql/connections.py", line 1057, in _read_query_result
    result.read()
  File "/Users/yuyang/github/djangblog/.venv/lib/python3.7/site-packages/pymysql/connections.py", line 1340, in read
    first_packet = self.connection._read_packet()
  File "/Users/yuyang/github/djangblog/.venv/lib/python3.7/site-packages/pymysql/connections.py", line 1014, in _read_packet
    packet.check_error()
  File "/Users/yuyang/github/djangblog/.venv/lib/python3.7/site-packages/pymysql/connections.py", line 393, in check_error
    err.raise_mysql_exception(self._data)
  File "/Users/yuyang/github/djangblog/.venv/lib/python3.7/site-packages/pymysql/err.py", line 107, in raise_mysql_exception
    raise errorclass(errno, errval)
django.db.utils.ProgrammingError: (1146, "Table 'blog.app_article' doesn't exist")
